<?xml version="1.0" ?>
<robot name="leg2" xmlns:xacro="http://www.ros.org/wiki/xacro">

<xacro:include filename="$(find leg2_description)/urdf/materials.xacro" />
<xacro:include filename="$(find leg2_description)/urdf/leg2.trans" />
<xacro:include filename="$(find leg2_description)/urdf/leg2.gazebo" />
<link name="base_link">
  <inertial>
    <origin rpy="0 0 0" xyz="-0.040787746026007786 -0.02111451815251765 0.1376231595379788"/>
    <mass value="0.06622023740694938"/>
    <inertia ixx="1.1e-05" ixy="-0.0" ixz="-0.0" iyy="1.8e-05" iyz="0.0" izz="8e-06"/>
  </inertial>
  <visual>
    <origin rpy="0 0 0" xyz="0 0 0"/>
    <geometry>
      <mesh filename="package://leg2_description/meshes/base_link.stl" scale="0.001 0.001 0.001"/>
    </geometry>
    <material name="silver"/>
  </visual>
  <collision>
    <origin rpy="0 0 0" xyz="0 0 0"/>
    <geometry>
      <mesh filename="package://leg2_description/meshes/base_link.stl" scale="0.001 0.001 0.001"/>
    </geometry>
  </collision>
</link>

<link name="Component1_Mirror___1__1_1_1">
  <inertial>
    <origin rpy="0 0 0" xyz="-0.002900781804186417 0.025112436018918757 -0.04359871686720297"/>
    <mass value="0.18142577340592403"/>
    <inertia ixx="0.000281" ixy="-2e-06" ixz="-0.0" iyy="0.00029" iyz="6e-06" izz="1.8e-05"/>
  </inertial>
  <visual>
    <origin rpy="0 0 0" xyz="0.04079 0.016228 -0.132102"/>
    <geometry>
      <mesh filename="package://leg2_description/meshes/Component1_Mirror___1__1_1_1.stl" scale="0.001 0.001 0.001"/>
    </geometry>
    <material name="silver"/>
  </visual>
  <collision>
    <origin rpy="0 0 0" xyz="0.04079 0.016228 -0.132102"/>
    <geometry>
      <mesh filename="package://leg2_description/meshes/Component1_Mirror___1__1_1_1.stl" scale="0.001 0.001 0.001"/>
    </geometry>
  </collision>
</link>

<link name="tibia_1_1_1">
  <inertial>
    <origin rpy="0 0 0" xyz="-0.04986513207289888 -0.00592119041929677 0.005272222836999563"/>
    <mass value="0.15554603496118452"/>
    <inertia ixx="8e-06" ixy="-1e-06" ixz="3e-06" iyy="0.000237" iyz="0.0" izz="0.000234"/>
  </inertial>
  <visual>
    <origin rpy="0 0 0" xyz="0.040789 -0.007772 -0.022102"/>
    <geometry>
      <mesh filename="package://leg2_description/meshes/tibia_1_1_1.stl" scale="0.001 0.001 0.001"/>
    </geometry>
    <material name="silver"/>
  </visual>
  <collision>
    <origin rpy="0 0 0" xyz="0.040789 -0.007772 -0.022102"/>
    <geometry>
      <mesh filename="package://leg2_description/meshes/tibia_1_1_1.stl" scale="0.001 0.001 0.001"/>
    </geometry>
  </collision>
</link>

<joint name="Rev14" type="continuous">
  <origin rpy="0 0 0" xyz="-0.04079 -0.016228 0.132102"/>
  <parent link="base_link"/>
  <child link="Component1_Mirror___1__1_1_1"/>
  <axis xyz="2e-06 1.0 0.0"/>
</joint>

<joint name="Rev15" type="continuous">
  <origin rpy="0 0 0" xyz="1e-06 0.024 -0.11"/>
  <parent link="Component1_Mirror___1__1_1_1"/>
  <child link="tibia_1_1_1"/>
  <axis xyz="2e-06 1.0 0.0"/>
</joint>

</robot>
