<?xml version="1.0" ?>
<robot name="leg2" xmlns:xacro="http://www.ros.org/wiki/xacro">

<xacro:include filename="$(find leg2_description)/urdf/materials.xacro" />
<xacro:include filename="$(find leg2_description)/urdf/leg2.trans" />
<xacro:include filename="$(find leg2_description)/urdf/leg2.gazebo" />
<link name="base_link">
  <inertial>
    <origin rpy="0 0 0" xyz="-0.035178677173068926 0.020361442759306778 0.14526924522292778"/>
    <mass value="0.07098555583740974"/>
    <inertia ixx="6.2e-05" ixy="-1e-05" ixz="4e-06" iyy="3.1e-05" iyz="2e-06" izz="7.5e-05"/>
  </inertial>
  <visual>
    <origin rpy="0 0 0" xyz="0 0 0"/>
    <geometry>
      <mesh filename="package://leg2_description/meshes/base_link.stl" scale="0.001 0.001 0.001"/>
    </geometry>
    <material name="silver"/>
  </visual>
  <collision>
    <origin rpy="0 0 0" xyz="0 0 0"/>
    <geometry>
      <mesh filename="package://leg2_description/meshes/base_link.stl" scale="0.001 0.001 0.001"/>
    </geometry>
  </collision>
</link>

<link name="thigh_1">
  <inertial>
    <origin rpy="0 0 0" xyz="-0.002104361960605823 0.017651626772934526 -0.042462025219402164"/>
    <mass value="0.058833278634128135"/>
    <inertia ixx="9.7e-05" ixy="0.0" ixz="-0.0" iyy="9.5e-05" iyz="1e-06" izz="9e-06"/>
  </inertial>
  <visual>
    <origin rpy="0 0 0" xyz="0.04079 0.016228 -0.132102"/>
    <geometry>
      <mesh filename="package://leg2_description/meshes/thigh_1.stl" scale="0.001 0.001 0.001"/>
    </geometry>
    <material name="silver"/>
  </visual>
  <collision>
    <origin rpy="0 0 0" xyz="0.04079 0.016228 -0.132102"/>
    <geometry>
      <mesh filename="package://leg2_description/meshes/thigh_1.stl" scale="0.001 0.001 0.001"/>
    </geometry>
  </collision>
</link>

<link name="tibia_1">
  <inertial>
    <origin rpy="0 0 0" xyz="-0.04986439883191778 0.008578809581268974 0.0052722228367173135"/>
    <mass value="0.028136989763679243"/>
    <inertia ixx="1e-06" ixy="-0.0" ixz="1e-06" iyy="4.3e-05" iyz="0.0" izz="4.2e-05"/>
  </inertial>
  <visual>
    <origin rpy="0 0 0" xyz="0.04079 0.007228 -0.022102"/>
    <geometry>
      <mesh filename="package://leg2_description/meshes/tibia_1.stl" scale="0.001 0.001 0.001"/>
    </geometry>
    <material name="silver"/>
  </visual>
  <collision>
    <origin rpy="0 0 0" xyz="0.04079 0.007228 -0.022102"/>
    <geometry>
      <mesh filename="package://leg2_description/meshes/tibia_1.stl" scale="0.001 0.001 0.001"/>
    </geometry>
  </collision>
</link>

<joint name="Rev16" type="continuous">
  <origin rpy="0 0 0" xyz="-0.04079 -0.016228 0.132102"/>
  <parent link="base_link"/>
  <child link="thigh_1"/>
  <axis xyz="2e-06 1.0 0.0"/>
</joint>

<joint name="Rev17" type="continuous">
  <origin rpy="0 0 0" xyz="0.0 0.009 -0.11"/>
  <parent link="thigh_1"/>
  <child link="tibia_1"/>
  <axis xyz="-2e-06 -1.0 -0.0"/>
</joint>

</robot>
